Workbook

Sheet Грунт
D1: Расчет выемки грунта при устройстве лотков | Q1: Ростверки | R1: Щебень под ростверки | S1: Щебень схема 2 | T1: Подб_Роств | U1: Бетон Роств | V1: Обратная засыпка
G2: Средняя высота hср, м | L2: Вычисления, Calculation Сечение, м2 | O2: Объем, м3 | Q2: шт | R2: Vщеб, м3 | S2: Vщеб, м3 | T2: Vподб м3 | U2: Vроств, м3 | V2: Vгр, м3 | W2: Объем, м3
A3: № участка | B3: Наименование работ | C3: Ед. изм. | D3: Захватки | E3: Длина лотка L, м | F3: Длина схема 2 L, м | G3: hср=(hmin+hmax)/2-hсущ. | L3: Sср=(Lверх.+Lниза)/2*hср | O3: V=Sср*L | Q3: V=1.200*0.900*0.600 | R3: V=0.200*1.700*2.000*N | S3: V=0.100*1.700*L | T3: V=0.100*1.300*1.600*N | U3: V=0.900*1.200*0.600*N | V3: Vгр=(2.100+3.400)/2*0.800*L | W3: V=Vгр -Vщеб-Vподб-Vроств
A4: 1 | B4: Выемка грунта класса V, Vth class soil excavation | C4: м3 | D4: Захватка 1 | E4: 17.5 | G4: hср= | H4: 1.663 | I4: 1.827 | J4: =CONCATENATE("(",H4,"+",I4,")/2-0.340") -> (1,663+1,827)/2-0.340 | K4: =(H4+I4)/2-0.34 -> 1.405 | L4: Sср= | M4: (5.100+2.100)/2*hср= | N4: =(5.1+2.1)/2*K4 -> 5.058 | O4: =N4*E4 -> 88.515 | Q4: 5 | R4: =Щебень!G4 -> 2.7 | S4: =Щебень!I4 -> 4.86 | T4: =Подб_Роств!G4 -> 1.04 | U4: =0.9*1.2*0.6*Q4 -> 3.24 | V4: =(2.1+3.4)/2*0.8*E4 -> 38.5 | W4: =V4-R4-T4-U4 -> 31.52
B5: Выемка грунта класса V, Vth class soil excavation | C5: м3 | D5: Захватка 2 | E5: =34.7 -> 34.7 | F5: 26.8 | G5: hср= | H5: 2.827 | I5: 3.201 | J5: =CONCATENATE("(",H5,"+",I5,")/2-0.340") -> (2,827+3,201)/2-0.340 | K5: =(H5+I5)/2-0.34 -> 2.674 | L5: Sср= | M5: (5.100+2.100)/2*hср= | N5: =(5.1+2.1)/2*K5 -> 9.6264 | O5: =N5*E5 -> 334.03608 | Q5: 4 | R5: =Щебень!G5 -> 2.16 | S5: =Щебень!I5 -> 0 | T5: =Подб_Роств!G5 -> 0.832 | U5: =0.9*1.2*0.6*Q5 -> 2.592 | V5: =(2.1+3.4)/2*0.8*E5 -> 76.34 | W5: =V5-R5-T5-U5 -> 70.756
E6: =SUM(E4:E5) -> 52.2 | F6: =SUM(F4:F5) -> 26.8 | O6: =SUM(O4:O5) -> 422.55108 | Q6: =SUM(Q4:Q5) -> 9 | R6: =SUM(R4:R5) -> 4.86 | S6: =SUM(S4:S5) -> 4.86 | T6: =SUM(T4:T5) -> 1.872 | U6: =SUM(U4:U5) -> 5.832 | V6: =SUM(V4:V5) -> 114.84 | W6: =SUM(W4:W5) -> 102.276
D7: Расчет выемки грунта при устройстве лотков | Q7: Ростверки | R7: Щебень под ростверки | S7: Щебень схема 2 | T7: Подб_Роств | U7: Бетон Роств | V7: Обратная засыпка
G8: Средняя высота hср, м | L8: Вычисления, Calculation Сечение, м2 | O8: Объем, м3 | Q8: шт | R8: Vщеб, м3 | S8: Vщеб, м3 | T8: Vподб м3 | U8: Vроств, м3 | V8: Vгр, м3 | W8: Объем, м3
A9: № участка | B9: Наименование работ | C9: Ед. изм. | D9: Захватки | E9: Длина лотка L, м | F9: Длина схема 2 L, м | G9: hср=(hmin+hmax)/2-hсущ. | L9: Sср=(Lверх.+Lниза)/2*hср | O9: V=Sср*L | Q9: V=1.200*0.900*0.600 | R9: V=0.200*1.700*2.000*N | S9: V=0.200*1.700*2.000*N | T9: V=0.100*1.300*1.600*N | U9: V=0.900*1.200*0.600*N | V9: Vгр=(2.100+3.400)/2*0.800*L | W9: V=Vгр -Vщеб-Vподб-Vроств
A10: 2 | B10: Выемка грунта класса V, Vth class soil excavation | C10: м3 | D10: Захватка 1 | E10: 54.2 | F10: 39 | G10: hср= | H10: 3.222 | I10: 3.845 | J10: =CONCATENATE("(",H10,"+",I10,")/2-0.340") -> (3,222+3,845)/2-0.340 | K10: =(H10+I10)/2-0.34 -> 3.1935 | L10: Sср= | M10: (5.100+2.100)/2*hср= | N10: =(5.1+2.1)/2*K10 -> 11.4966 | O10: =N10*E10 -> 623.11572 | Q10: 4 | R10: =Щебень!G12 -> 2.16 | S10: =Щебень!I12 -> 5.4 | T10: =Подб_Роств!G12 -> 0.832 | U10: =0.9*1.2*0.6*Q10 -> 2.592 | V10: =(2.1+3.4)/2*0.8*E10 -> 119.24 | W10: =V10-R10-T10-U10 -> 113.656
B11: Выемка грунта класса V, Vth class soil excavation | C11: м3 | D11: Захватка 2 | E11: 21.5 | G11: hср= | H11: 1.658 | I11: 1.902 | J11: =CONCATENATE("(",H11,"+",I11,")/2-0.340") -> (1,658+1,902)/2-0.340 | K11: =(H11+I11)/2-0.34 -> 1.44 | L11: Sср= | M11: (5.100+2.100)/2*hср= | N11: =(5.1+2.1)/2*K11 -> 5.184 | O11: =N11*E11 -> 111.456 | Q11: 6 | R11: =Щебень!G13 -> 3.24 | S11: =Щебень!I13 -> 0 | T11: =Подб_Роств!G13 -> 1.248 | U11: =0.9*1.2*0.6*Q11 -> 3.888 | V11: =(2.1+3.4)/2*0.8*E11 -> 47.3 | W11: =V11-R11-T11-U11 -> 38.924
E12: =SUM(E10:E11) -> 75.7 | F12: =SUM(F10:F11) -> 39 | O12: =SUM(O10:O11) -> 734.57172 | Q12: =SUM(Q10:Q11) -> 10 | R12: =SUM(R10:R11) -> 5.4 | S12: =SUM(S10:S11) -> 5.4 | T12: =SUM(T10:T11) -> 2.08 | U12: =SUM(U10:U11) -> 6.48 | V12: =SUM(V10:V11) -> 166.54 | W12: =SUM(W10:W11) -> 152.58
D13: Расчет выемки грунта при устройстве лотков | Q13: Ростверки | R13: Щебень под ростверки | S13: Щебень схема 2 | T13: Подб_Роств | U13: Бетон Роств | V13: Обратная засыпка
G14: Средняя высота hср, м | L14: Вычисления, Calculation Сечение, м2 | O14: Объем, м3 | Q14: шт | R14: Vщеб, м3 | S14: Vщеб, м3 | T14: Vподб м3 | U14: Vроств, м3 | V14: Vгр, м3 | W14: Объем, м3
A15: № участка | B15: Наименование работ | C15: Ед. изм. | D15: Захватки | E15: Длина лотка L, м | F15: Длина схема 2 L, м | G15: hср=(hmin+hmax)/2-hсущ. | L15: Sср=(Lверх.+Lниза)/2*hср | O15: V=Sср*L | Q15: V=1.200*0.900*0.600 | R15: V=0.200*1.700*2.000*N | S15: V=0.200*1.700*2.000*N | T15: V=0.100*1.300*1.600*N | U15: V=0.900*1.200*0.600*N | V15: Vгр=(2.100+3.400)/2*0.800*L | W15: V=Vгр -Vщеб-Vподб-Vроств
A16: 3 | B16: Выемка грунта класса V, Vth class soil excavation | C16: м3 | D16: Захватка 1 | E16: =39+3.9 -> 42.9 | F16: 29.8 | G16: hср= | H16: 3.341 | I16: 3.88 | J16: =CONCATENATE("(",H16,"+",I16,")/2-0.340") -> (3,341+3,88)/2-0.340 | K16: =(H16+I16)/2-0.34 -> 3.2705 | L16: Sср= | M16: (5.100+2.100)/2*hср= | N16: =(5.1+2.1)/2*K16 -> 11.7738 | O16: =N16*E16 -> 505.09602 | Q16: 3 | R16: =Щебень!G20 -> 1.62 | S16: =Щебень!I20 -> 6.48 | T16: =Подб_Роств!G20 -> 0.624 | U16: =0.9*1.2*0.6*Q16 -> 1.944 | V16: =(2.1+3.4)/2*0.8*E16 -> 94.38 | W16: =V16-R16-T16-U16 -> 90.192
B17: Выемка грунта класса V, Vth class soil excavation | C17: м3 | D17: Захватка 2 | E17: 20.9 | G17: hср= | H17: 1.18 | I17: 2.48 | J17: =CONCATENATE("(",H17,"+",I17,")/2-0.340") -> (1,18+2,48)/2-0.340 | K17: =(H17+I17)/2-0.34 -> 1.49 | L17: Sср= | M17: (5.100+2.100)/2*hср= | N17: =(5.1+2.1)/2*K17 -> 5.364 | O17: =N17*E17 -> 112.1076 | Q17: 6 | R17: =Щебень!G21 -> 3.24 | S17: =Щебень!I21 -> 0 | T17: =Подб_Роств!G21 -> 1.248 | U17: =0.9*1.2*0.6*Q17 -> 3.888 | V17: =(2.1+3.4)/2*0.8*E17 -> 45.98 | W17: =V17-R17-T17-U17 -> 37.604
B18: Выемка грунта класса V, Vth class soil excavation | C18: м3 | D18: Захватка 3 | E18: 12.5 | F18: 11.7 | G18: hср= | H18: 2.612 | I18: 2.717 | J18: =CONCATENATE("(",H18,"+",I18,")/2-0.340") -> (2,612+2,717)/2-0.340 | K18: =(H18+I18)/2-0.34 -> 2.3245 | L18: Sср= | M18: (5.100+2.100)/2*hср= | N18: =(5.1+2.1)/2*K18 -> 8.3682 | O18: =N18*E18 -> 104.6025 | Q18: 0 | R18: =Щебень!G22 -> 0 | S18: =Щебень!I22 -> 0 | T18: =Подб_Роств!G22 -> 0 | U18: =0.9*1.2*0.6*Q18 -> 0 | V18: =(2.1+3.4)/2*0.8*E18 -> 27.5 | W18: =V18-R18-T18-U18 -> 27.5
B19: Выемка грунта класса V, Vth class soil excavation | C19: м3 | D19: Захватка 4 | E19: 42.1 | F19: 28.1 | G19: hср= | H19: 3.004 | I19: 3.44 | J19: =CONCATENATE("(",H19,"+",I19,")/2-0.340") -> (3,004+3,44)/2-0.340 | K19: =(H19+I19)/2-0.34 -> 2.882 | L19: Sср= | M19: (5.100+2.100)/2*hср= | N19: =(5.1+2.1)/2*K19 -> 10.3752 | O19: =N19*E19 -> 436.79592 | Q19: 3 | R19: =Щебень!G23 -> 1.62 | S19: =Щебень!I23 -> 0 | T19: =Подб_Роств!G23 -> 1.272 | U19: =1.2*1.25*0.6*Q19 -> 2.7 | V19: =(2.1+3.4)/2*0.8*E19 -> 92.62 | W19: =V19-R19-T19-U19 -> 87.028
E20: =SUM(E16:E19) -> 118.4 | F20: =SUM(F16:F19) -> 69.6 | O20: =SUM(O16:O19) -> 1158.602 | Q20: =SUM(Q16:Q19) -> 12 | R20: =SUM(R16:R19) -> 6.48 | S20: =SUM(S16:S19) -> 6.48 | T20: =SUM(T16:T19) -> 3.144 | U20: =SUM(U16:U19) -> 8.532 | V20: =SUM(V16:V19) -> 260.48 | W20: =SUM(W16:W19) -> 242.324
D21: Расчет выемки грунта при устройстве лотков | Q21: Ростверки | R21: Щебень под ростверки | S21: Щебень схема 2 | T21: Подб_Роств | U21: Бетон Роств | V21: Обратная засыпка
G22: Средняя высота hср, м | L22: Вычисления, Calculation Сечение, м2 | O22: Объем, м3 | Q22: шт | R22: Vщеб, м3 | S22: Vщеб, м3 | T22: Vподб м3 | U22: Vроств, м3 | V22: Vгр, м3 | W22: Объем, м3
A23: № участка | B23: Наименование работ | C23: Ед. изм. | D23: Захватки | E23: Длина лотка L, м | F23: Длина схема 2 L, м | G23: hср=(hmin+hmax)/2-hсущ. | L23: Sср=(Lверх.+Lниза)/2*hср | O23: V=Sср*L | Q23: V=1.200*0.900*0.600 | R23: V=0.200*1.700*2.000*N | S23: V=0.200*1.700*2.000*N | T23: V=0.100*1.300*1.600*N | U23: V=0.900*1.200*0.600*N | V23: Vгр=(2.100+3.400)/2*0.800*L | W23: V=Vгр -Vщеб-Vподб-Vроств
A24: 4 | B24: Выемка грунта класса V, Vth class soil excavation | C24: м3 | D24: Захватка 1 | E24: =67.6+3.1*4 -> 80 | F24: 31.7 | G24: hср= | H24: 2.626 | I24: 3.441 | J24: =CONCATENATE("(",H24,"+",I24,")/2-0.340") -> (2,626+3,441)/2-0.340 | K24: =(H24+I24)/2-0.34 -> 2.6935 | L24: Sср= | M24: (5.100+2.100)/2*hср= | N24: =(5.1+2.1)/2*K24 -> 9.6966 | O24: =N24*E24 -> 775.728 | Q24: 13 | R24: =Щебень!G32 -> 7.02 | S24: =Щебень!I32 -> 15.66 | T24: =Подб_Роств!G32 -> 2.704 | U24: =0.9*1.2*0.6*Q24 -> 8.424 | V24: =(2.1+3.4)/2*0.8*E24 -> 176 | W24: =V24-R24-T24-U24 -> 157.852
B25: Выемка грунта класса V, Vth class soil excavation | C25: м3 | D25: Захватка 2 | E25: 23.3 | F25: 9.8 | G25: hср= | H25: 2.688 | I25: 2.887 | J25: =CONCATENATE("(",H25,"+",I25,")/2-0.340") -> (2,688+2,887)/2-0.340 | K25: =(H25+I25)/2-0.34 -> 2.4475 | L25: Sср= | M25: (5.100+2.100)/2*hср= | N25: =(5.1+2.1)/2*K25 -> 8.811 | O25: =N25*E25 -> 205.2963 | Q25: 3 | R25: =Щебень!G33 -> 1.62 | S25: =Щебень!I33 -> 0 | T25: =Подб_Роств!G33 -> 0.624 | U25: =0.9*1.2*0.6*Q25 -> 1.944 | V25: =(2.1+3.4)/2*0.8*E25 -> 51.26 | W25: =V25-R25-T25-U25 -> 47.072
B26: Выемка грунта класса V, Vth class soil excavation | C26: м3 | D26: Захватка 3 | E26: 58.5 | F26: 9.5 | G26: hср= | H26: 1.674 | I26: 1.877 | J26: =CONCATENATE("(",H26,"+",I26,")/2-0.340") -> (1,674+1,877)/2-0.340 | K26: =(H26+I26)/2-0.34 -> 1.4355 | L26: Sср= | M26: (5.100+2.100)/2*hср= | N26: =(5.1+2.1)/2*K26 -> 5.1678 | O26: =N26*E26 -> 302.3163 | Q26: 13 | R26: =Щебень!G34 -> 7.02 | S26: =Щебень!I34 -> 0 | T26: =Подб_Роств!G34 -> 2.704 | U26: =0.9*1.2*0.6*Q26 -> 8.424 | V26: =(2.1+3.4)/2*0.8*E26 -> 128.7 | W26: =V26-R26-T26-U26 -> 110.552
E27: =SUM(E24:E26) -> 161.8 | F27: =SUM(F24:F26) -> 51 | O27: =SUM(O24:O26) -> 1283.3406 | Q27: =SUM(Q24:Q26) -> 29 | R27: =SUM(R24:R26) -> 15.66 | S27: =SUM(S24:S26) -> 15.66 | T27: =SUM(T24:T26) -> 6.032 | U27: =SUM(U24:U26) -> 18.792 | V27: =SUM(V24:V26) -> 355.96 | W27: =SUM(W24:W26) -> 315.476
E29: =E6+E12+E20+E27 -> 408.1 | F29: =F6+F12+F20+F27 -> 186.4 | O29: =O6+O12+O20+O27 -> 3599.0654 | Q29: =Q6+Q12+Q20+Q27 -> 60 | R29: =R6+R12+R20+R27 -> 32.4 | S29: =S6+S12+S20+S27 -> 32.4 | T29: =T6+T12+T20+T27 -> 13.128 | U29: =U6+U12+U20+U27 -> 39.636 | V29: =V6+V12+V20+V27 -> 897.82 | W29: =W6+W12+W20+W27 -> 812.656

Sheet Щебень
A1: Устройство основания из щебня фракции 20-40 ГОСТ 54748-2011 толщиной 200 мм/ Installation of base of gravel fr. 20-40 GOST 54748-2011 200 mm thick
E2: N | F2: L | G2: Вычисления, Calculation Объем , м3 | H2: Вычисления, Calculation Объем , м3 | I2: Всего
A3: № участка | B3: Наименование работ | C3: Ед. изм. | D3: Захватки | E3: Ростверки шт | F3: Длина основания, м | G3: V=0.200*1.500*1.800*N | H3: V=0.100*1.700*L | I3: м3
A4: 1 | B4: Устройство основания из щебня под ростверки | C4: м3 | D4: Захватка 1 | E4: =Грунт!Q4 -> 5 | G4: =0.2*1.5*1.8*E4 -> 2.7 | I4: =SUM(G4:G5) -> 4.86
C5: м3 | D5: Захватка 2 | E5: =Грунт!Q5 -> 4 | G5: =0.2*1.5*1.8*E5 -> 2.16
B6: Устройство основания из щебня под Лотки | C6: м3 | D6: Захватка 1 | F6: =Грунт!F4 -> 0 | H6: =0.1*1.7*F6 -> 0 | I6: =SUM(H6:H7) -> 4.556
C7: м3 | D7: Захватка 2 | F7: =Грунт!F5 -> 26.8 | H7: =0.1*1.7*F7 -> 4.556
I8: =SUM(I4:I7) -> 9.416
A9: Устройство основания из щебня фракции 20-40 ГОСТ 54748-2011 толщиной 200 мм/ Installation of base of gravel fr. 20-40 GOST 54748-2011 200 mm thick
E10: N | F10: L | G10: Вычисления, Calculation Объем , м3 | H10: Вычисления, Calculation Объем , м3 | I10: Всего
A11: № участка | B11: Наименование работ | C11: Ед. изм. | D11: Захватки | E11: Ростверки шт | F11: Длина основания, м | G11: V=0.200*1.500*1.800*N | H11: V=0.100*1.700*L | I11: м3
A12: 2 | B12: Устройство основания из щебня под ростверки | C12: м3 | D12: Захватка 1 | E12: =Грунт!Q10 -> 4 | G12: =0.2*1.5*1.8*E12 -> 2.16 | I12: =SUM(G12:G13) -> 5.4
C13: м3 | D13: Захватка 2 | E13: =Грунт!Q11 -> 6 | G13: =0.2*1.5*1.8*E13 -> 3.24
B14: Устройство основания из щебня под Лотки | C14: м3 | D14: Захватка 1 | F14: =Грунт!F10 -> 39 | H14: =0.1*1.7*F14 -> 6.63 | I14: =SUM(H14:H15) -> 6.63
C15: м3 | D15: Захватка 2 | F15: =Грунт!F11 -> 0 | H15: =0.1*1.7*F15 -> 0
I16: =SUM(I12:I15) -> 12.03
A17: Устройство основания из щебня фракции 20-40 ГОСТ 54748-2011 толщиной 200 мм/ Installation of base of gravel fr. 20-40 GOST 54748-2011 200 mm thick
E18: N | F18: L | G18: Вычисления, Calculation Объем , м3 | H18: Вычисления, Calculation Объем , м3 | I18: Всего
A19: № участка | B19: Наименование работ | C19: Ед. изм. | D19: Захватки | E19: Ростверки шт | F19: Длина основания, м | G19: V=0.200*1.500*1.800*N | H19: V=0.100*1.700*L | I19: м3
A20: 3 | B20: Устройство основания из щебня под ростверки | C20: м3 | D20: Захватка 1 | E20: =Грунт!Q16 -> 3 | G20: =0.2*1.5*1.8*E20 -> 1.62 | I20: =SUM(G20:G23) -> 6.48
C21: м3 | D21: Захватка 2 | E21: =Грунт!Q17 -> 6 | G21: =0.2*1.5*1.8*E21 -> 3.24
C22: м3 | D22: Захватка 3 | E22: =Грунт!Q18 -> 0 | G22: =0.2*1.5*1.8*E22 -> 0
C23: м3 | D23: Захватка 4 | E23: =Грунт!Q19 -> 3 | G23: =0.2*1.5*1.8*E23 -> 1.62
B24: Устройство основания из щебня под Лотки | C24: м3 | D24: Захватка 1 | F24: =Грунт!F16 -> 29.8 | G24: =0.2*1.5*1.8*E24 -> 0 | H24: =0.1*1.7*F24 -> 5.066 | I24: =SUM(H24:H27) -> 11.832
C25: м3 | D25: Захватка 2 | F25: =Грунт!F17 -> 0 | H25: =0.1*1.7*F25 -> 0
C26: м3 | D26: Захватка 3 | F26: =Грунт!F18 -> 11.7 | H26: =0.1*1.7*F26 -> 1.989
C27: м3 | D27: Захватка 4 | F27: =Грунт!F19 -> 28.1 | H27: =0.1*1.7*F27 -> 4.777
I28: =SUM(I20:I27) -> 18.312
A29: Устройство основания из щебня фракции 20-40 ГОСТ 54748-2011 толщиной 200 мм/ Installation of base of gravel fr. 20-40 GOST 54748-2011 200 mm thick
E30: N | F30: L | G30: Вычисления, Calculation Объем , м3 | H30: Вычисления, Calculation Объем , м3 | I30: Всего
A31: № участка | B31: Наименование работ | C31: Ед. изм. | D31: Захватки | E31: Ростверки шт | F31: Длина основания, м | G31: V=0.200*1.500*1.800*N | H31: V=0.100*1.700*L | I31: м3
A32: 4 | B32: Устройство основания из щебня под ростверки | C32: м3 | D32: Захватка 1 | E32: =Грунт!Q24 -> 13 | G32: =0.2*1.5*1.8*E32 -> 7.02 | I32: =SUM(G32:G34) -> 15.66
C33: м3 | D33: Захватка 2 | E33: =Грунт!Q25 -> 3 | G33: =0.2*1.5*1.8*E33 -> 1.62
C34: м3 | D34: Захватка 3 | E34: =Грунт!Q26 -> 13 | G34: =0.2*1.5*1.8*E34 -> 7.02
B35: Устройство основания из щебня под Лотки | C35: м3 | D35: Захватка 1 | F35: =Грунт!F24 -> 31.7 | H35: =0.1*1.7*F35 -> 5.389 | I35: =SUM(H35:H37) -> 8.67
C36: м3 | D36: Захватка 2 | F36: =Грунт!F25 -> 9.8 | H36: =0.1*1.7*F36 -> 1.666
C37: м3 | D37: Захватка 3 | F37: =Грунт!F26 -> 9.5 | H37: =0.1*1.7*F37 -> 1.615
I38: =SUM(I32:I37) -> 24.33
E40: =SUM(E4:E34) -> 60 | F40: =SUM(F4:F38) -> 186.4 | I40: =I38+I28+I16+I8 -> 64.088
I43: =I40-31.69 -> 32.398

Sheet Подб_Роств
A1: Бетонное основание, B15, B25, B30 толщ. 100 мм/Concrete bed, B15, B25, B30 th. 100 mm
E2: N | F2: L | G2: Вычисления, Calculation Объем , м3 | H2: Вычисления, Calculation Объем , м3 | I2: Всего
A3: № участка | B3: Наименование работ | C3: Ед. изм. | D3: Захватки | E3: Ростверки шт | F3: Длина основания, м | G3: V=0.100*1.300*1.600*N | H3: V=0.300*1.7*L
A4: 1 | B4: Бетонное основание под ростверки | C4: м3 | D4: Захватка 1 | E4: =Грунт!Q4 -> 5 | G4: =0.1*1.3*1.6*E4 -> 1.04 | I4: =SUM(G4:H5) -> 1.872
C5: м3 | D5: Захватка 2 | E5: =Грунт!Q5 -> 4 | G5: =0.1*1.3*1.6*E5 -> 0.832
B6: Бетонное основание по грунту | C6: м3 | D6: Захватка 1 | H6: =0.3*1.7*F6 -> 0 | I6: =SUM(G6:H7) -> 13.668
C7: м3 | D7: Захватка 2 | F7: =Грунт!F6 -> 26.8 | H7: =0.3*1.7*F7 -> 13.668
G8: =SUM(G4:G7) -> 1.872 | H8: =SUM(H4:H7) -> 13.668 | I8: =SUM(I4:I7) -> 15.54
A9: Бетонное основание, B15, W6, толщ. 100 мм/Concrete bed, B15, W6, th. 100 mm
E10: N | F10: L | G10: Вычисления, Calculation Объем , м3 | H10: Вычисления, Calculation Объем , м3 | I10: Всего
A11: № участка | B11: Наименование работ | C11: Ед. изм. | D11: Захватки | E11: Ростверки шт | F11: Длина основания, м | G11: V=0.100*1.300*1.600*N | H11: V=0.300*1.7*L
A12: 2 | B12: Бетонное основание под ростверки | C12: м3 | D12: Захватка 1 | E12: =Грунт!Q10 -> 4 | G12: =0.1*1.3*1.6*E12 -> 0.832 | I12: =SUM(G12:G13) -> 2.08
C13: м3 | D13: Захватка 2 | E13: =Грунт!Q11 -> 6 | G13: =0.1*1.3*1.6*E13 -> 1.248
B14: Бетонное основание по грунту | C14: м3 | D14: Захватка 1 | F14: =Грунт!F12 -> 39 | H14: =0.3*1.7*F14 -> 19.89 | I14: =SUM(G14:H15) -> 19.89
C15: м3 | D15: Захватка 2 | F15: =Грунт!F13 -> 0 | H15: =0.3*1.7*F15 -> 0
G16: =SUM(G12:G15) -> 2.08 | H16: =SUM(H12:H15) -> 19.89 | I16: =SUM(I12:I15) -> 21.97
A17: Бетонное основание, B15, W6, толщ. 100 мм/Concrete bed, B15, W6, th. 100 mm
E18: N | F18: L | G18: Вычисления, Calculation Объем , м3 | H18: Вычисления, Calculation Объем , м3 | I18: Всего
A19: № участка | B19: Наименование работ | C19: Ед. изм. | D19: Захватки | E19: Ростверки шт | F19: Длина основания, м | G19: V=0.100*1.300*1.600*N | H19: V=0.300*1.7*L
A20: 3 | B20: Бетонное основание под ростверки | C20: м3 | D20: Захватка 1 | E20: =Грунт!Q16 -> 3 | G20: =0.1*1.3*1.6*E20 -> 0.624 | I20: =SUM(G20:G23) -> 3.144
C21: м3 | D21: Захватка 2 | E21: =Грунт!Q17 -> 6 | G21: =0.1*1.3*1.6*E21 -> 1.248
C22: м3 | D22: Захватка 3 | E22: =Грунт!Q18 -> 0 | G22: =0.1*1.3*1.6*E22 -> 0
C23: м3 | D23: Захватка 4 | E23: =Грунт!Q19 -> 3 | G23: =0.1*1.6*2.65*E23 -> 1.272
B24: Бетонное основание по грунту | C24: м3 | D24: Захватка 1 | F24: =Грунт!F16 -> 29.8 | H24: =0.3*1.7*F24 -> 15.198 | I24: =SUM(H24:H27) -> 35.496
C25: м3 | D25: Захватка 2 | F25: =Грунт!F17 -> 0 | H25: =0.3*1.7*F25 -> 0
C26: м3 | D26: Захватка 3 | F26: =Грунт!F18 -> 11.7 | H26: =0.3*1.7*F26 -> 5.967
C27: м3 | D27: Захватка 4 | F27: =Грунт!F19 -> 28.1 | H27: =0.3*1.7*F27 -> 14.331
G28: =SUM(G20:G27) -> 3.144 | H28: =SUM(H20:H27) -> 35.496 | I28: =SUM(I20:I27) -> 38.64
A29: Бетонное основание, B15, B30 толщ. 100 мм/Concrete bed, B15, B30 th. 100 mm
E30: N | F30: L | G30: Вычисления, Calculation Объем , м3 | H30: Вычисления, Calculation Объем , м3 | I30: Всего
A31: № участка | B31: Наименование работ | C31: Ед. изм. | D31: Захватки | E31: Ростверки шт | F31: Длина основания, м | G31: V=0.100*1.300*1.600*N | H31: V=0.300*1.7*L
A32: 4 | B32: Бетонное основание под ростверки | C32: м3 | D32: Захватка 1 | E32: =Грунт!Q24 -> 13 | G32: =0.1*1.3*1.6*E32 -> 2.704 | I32: =SUM(G32:G34) -> 6.032
C33: м3 | D33: Захватка 2 | E33: =Грунт!Q25 -> 3 | G33: =0.1*1.3*1.6*E33 -> 0.624
C34: м3 | D34: Захватка 3 | E34: =Грунт!Q26 -> 13 | G34: =0.1*1.3*1.6*E34 -> 2.704
B35: Бетонное основание по грунту | C35: м3 | D35: Захватка 1 | F35: =Грунт!F24 -> 31.7 | H35: =0.3*1.7*F35 -> 16.167 | I35: =SUM(H35:H37) -> 26.01
C36: м3 | D36: Захватка 2 | F36: =Грунт!F25 -> 9.8 | H36: =0.3*1.7*F36 -> 4.998
C37: м3 | D37: Захватка 3 | F37: =Грунт!F26 -> 9.5 | H37: =0.3*1.7*F37 -> 4.845
G38: =SUM(G32:G37) -> 6.032 | H38: =SUM(H32:H37) -> 26.01 | I38: =SUM(I32:I37) -> 32.042
E40: =SUM(E4:E34) -> 60 | F40: =SUM(F4:F37) -> 186.4 | G40: =G8+G16+G28+G38 -> 13.128 | H40: =H8+H16+H28+H38 -> 95.064 | I40: =I8+I16+I28+I38 -> 108.192

Sheet Ростверки
A1: Бетонирование ростверков B25 W8, Песчаное основание
E2: N | F2: L | G2: Вычисления, Calculation Объем Бетона , м3 | H2: Вычисления, Calculation Объем Песка, м3
A3: № участка | B3: Наименование работ | C3: Ед. изм. | D3: Захватки | E3: Ростверки шт | F3: Длина основания, м | G3: V=0.900*1.200*0.600*N | H3: V=0.300*1.700*L
A4: 1 | B4: Бетонирование ростверков | C4: м3 | D4: Захватка 1 | E4: =Грунт!Q4 -> 5 | G4: =0.9*1.2*0.6*E4 -> 3.24
C5: м3 | D5: Захватка 2 | E5: =Грунт!Q5 -> 4 | G5: =0.9*1.2*0.6*E5 -> 2.592
B6: Песчаное основание | C6: м3 | D6: Захватка 1 | F6: =Грунт!F4 -> 0 | H6: =0.3*1.7*F6 -> 0
C7: м3 | D7: Захватка 2 | F7: =Грунт!F5 -> 26.8 | H7: =0.3*1.7*F7 -> 13.668
G8: =SUM(G4:G7) -> 5.832 | H8: =SUM(H4:H7) -> 13.668
A9: Бетонирование ростверков B25 W8, Песчаное основание
E10: N | F10: L | G10: Вычисления, Calculation Объем Бетона , м3 | H10: Вычисления, Calculation Объем Песка, м3
A11: № участка | B11: Наименование работ | C11: Ед. изм. | D11: Захватки | E11: Ростверки шт | F11: Длина основания, м | G11: V=0.900*1.200*0.600*N | H11: V=0.300*1.700*L
A12: 2 | B12: Бетонирование ростверков | C12: м3 | D12: Захватка 1 | E12: =Грунт!Q10 -> 4 | G12: =0.9*1.2*0.6*E12 -> 2.592
C13: м3 | D13: Захватка 2 | E13: =Грунт!Q11 -> 6 | G13: =0.9*1.2*0.6*E13 -> 3.888
B14: Песчаное основание | C14: м3 | D14: Захватка 1 | F14: =Грунт!F12 -> 39 | H14: =0.3*1.7*F14 -> 19.89
C15: м3 | D15: Захватка 2 | F15: =Грунт!F13 -> 0 | H15: =0.3*1.7*F15 -> 0
G16: =SUM(G12:G15) -> 6.48 | H16: =SUM(H12:H15) -> 19.89
A17: Бетонирование ростверков B25 W8, Песчаное основание
E18: N | F18: L | G18: Вычисления, Calculation Объем Бетона , м3 | H18: Вычисления, Calculation Объем Песка, м3
A19: № участка | B19: Наименование работ | C19: Ед. изм. | D19: Захватки | E19: Ростверки шт | F19: Длина основания, м | G19: V=0.900*1.200*0.600*N | H19: V=0.300*1.700*L
A20: 3 | B20: Бетонирование ростверков | C20: м3 | D20: Захватка 1 | E20: =Грунт!Q16 -> 3 | G20: =0.9*1.2*0.6*E20 -> 1.944
C21: м3 | D21: Захватка 2 | E21: =Грунт!Q17 -> 6 | G21: =0.9*1.2*0.6*E21 -> 3.888
C22: м3 | D22: Захватка 3 | E22: =Грунт!Q18 -> 0 | G22: =0.9*1.2*0.6*E22 -> 0
C23: м3 | D23: Захватка 4 | E23: =Грунт!Q19 -> 3 | G23: =1.2*1.25*0.6*E23 -> 2.7
B24: Песчаное основание | C24: м3 | D24: Захватка 1 | F24: =Грунт!F16 -> 29.8 | H24: =0.3*1.7*F24 -> 15.198
C25: м3 | D25: Захватка 2 | F25: =Грунт!F17 -> 0 | H25: =0.3*1.7*F25 -> 0
C26: м3 | D26: Захватка 3 | F26: =Грунт!F18 -> 11.7 | H26: =0.3*1.7*F26 -> 5.967
C27: м3 | D27: Захватка 4 | F27: =Грунт!F19 -> 28.1 | H27: =0.3*1.7*F27 -> 14.331
G28: =SUM(G20:G27) -> 8.532 | H28: =SUM(H20:H27) -> 35.496
A29: Бетонирование ростверков B25 W8, Песчаное основание
E30: N | F30: L | G30: Вычисления, Calculation Объем Бетона , м3 | H30: Вычисления, Calculation Объем Песка, м3
A31: № участка | B31: Наименование работ | C31: Ед. изм. | D31: Захватки | E31: Ростверки шт | F31: Длина основания, м | G31: V=0.900*1.200*0.600*N | H31: V=0.300*1.700*L
A32: 4 | B32: Бетонирование ростверков | C32: м3 | D32: Захватка 1 | E32: =Грунт!Q24 -> 13 | G32: =0.9*1.2*0.6*E32 -> 8.424
C33: м3 | D33: Захватка 2 | E33: =Грунт!Q25 -> 3 | G33: =0.9*1.2*0.6*E33 -> 1.944
C34: м3 | D34: Захватка 3 | E34: =Грунт!Q26 -> 13 | G34: =0.9*1.2*0.6*E34 -> 8.424
B35: Песчаное основание | C35: м3 | D35: Захватка 1 | F35: =Грунт!F24 -> 31.7 | H35: =0.3*1.7*F35 -> 16.167
C36: м3 | D36: Захватка 2 | F36: =Грунт!F25 -> 9.8 | H36: =0.3*1.7*F36 -> 4.998
C37: м3 | D37: Захватка 3 | F37: =Грунт!F26 -> 9.5 | H37: =0.3*1.7*F37 -> 4.845
G38: =SUM(G32:G37) -> 18.792 | H38: =SUM(H32:H37) -> 26.01
E40: =SUM(E4:E34) -> 60 | F40: =SUM(F4:F37) -> 186.4 | G40: =G38+G28+G16+G8 -> 39.636 | H40: =H38+H28+H16+H8 -> 95.064

Sheet Обр_Засып_Роств
A1: Расчет обратной засыпки ростверков при устройстве лотков
D2: Ростверки | E2: Щебень | F2: Подб_Роств | G2: Бетон Роств | H2: Обратная засыпка
D3: шт | E3: Vщеб, м3 | F3: Vподб м3 | G3: Vроств, м3 | H3: Vгр, м3 | I3: Объем, м3
A4: № участка | B4: Захватки | C4: Длина лотка L, м | E4: V=0.200*1.700*2.000*N | F4: V=0.100*1.300*1.600*N | G4: V=0.900*1.200*0.500*N | H4: Vгр=(2.100+3.400)/2*0.800*L | I4: V=Vгр -Vщеб-Vподб-Vроств
A5: 1 | B5: Захватка 1 | C5: =Грунт!E4 -> 17.5 | D5: =Грунт!Q4 -> 5 | E5: =Щебень!G4 -> 2.7 | F5: =Подб_Роств!G4 -> 1.04 | G5: =Ростверки!G4 -> 3.24 | H5: =(2.1+3.4)/2*0.8*C5 -> 38.5 | I5: =H5-G5-F5-E5 -> 31.52
B6: Захватка 2 | C6: =Грунт!E5 -> 34.7 | D6: =Грунт!Q5 -> 4 | E6: =Щебень!G5 -> 2.16 | F6: =Подб_Роств!G5 -> 0.832 | G6: =Ростверки!G5 -> 2.592 | H6: =(2.1+3.4)/2*0.8*C6 -> 76.34 | I6: =H6-G6-F6-E6 -> 70.756
B7: TOTAL: | C7: =SUM(C5:C6) -> 52.2 | D7: =SUM(D5:D6) -> 9 | E7: =SUM(E5:E6) -> 4.86 | F7: =SUM(F5:F6) -> 1.872 | G7: =SUM(G5:G6) -> 5.832 | H7: =SUM(H5:H6) -> 114.84 | I7: =SUM(I5:I6) -> 102.276
A9: Расчет обратной засыпки ростверков при устройстве лотков
D10: Ростверки | E10: Щебень | F10: Подб_Роств | G10: Бетон Роств | H10: Обратная засыпка
D11: шт | E11: Vщеб, м3 | F11: Vподб м3 | G11: Vроств, м3 | H11: Vгр, м3 | I11: Объем, м3
A12: № участка | B12: Захватки | C12: Длина лотка L, м | E12: V=0.200*1.700*2.000*N | F12: V=0.100*1.300*1.600*N | G12: V=0.900*1.200*0.500*N | H12: Vгр=(2.100+3.400)/2*0.800*L | I12: V=Vгр -Vщеб-Vподб-Vроств
A13: 2 | B13: Захватка 1 | C13: =Грунт!E10 -> 54.2 | D13: =Грунт!Q10 -> 4 | E13: =Щебень!G12 -> 2.16 | F13: =Подб_Роств!G12 -> 0.832 | G13: =Ростверки!G12 -> 2.592 | H13: =(2.1+3.4)/2*0.8*C13 -> 119.24 | I13: =H13-G13-F13-E13 -> 113.656
B14: Захватка 2 | C14: =Грунт!E11 -> 21.5 | D14: =Грунт!Q11 -> 6 | E14: =Щебень!G13 -> 3.24 | F14: =Подб_Роств!G13 -> 1.248 | G14: =Ростверки!G13 -> 3.888 | H14: =(2.1+3.4)/2*0.8*C14 -> 47.3 | I14: =H14-G14-F14-E14 -> 38.924
B15: TOTAL: | C15: =SUM(C13:C14) -> 75.7 | D15: =SUM(D13:D14) -> 10 | E15: =SUM(E13:E14) -> 5.4 | F15: =SUM(F13:F14) -> 2.08 | G15: =SUM(G13:G14) -> 6.48 | H15: =SUM(H13:H14) -> 166.54 | I15: =SUM(I13:I14) -> 152.58
A17: Расчет обратной засыпки ростверков при устройстве лотков
D18: Ростверки | E18: Щебень | F18: Подб_Роств | G18: Бетон Роств | H18: Обратная засыпка
D19: шт | E19: Vщеб, м3 | F19: Vподб м3 | G19: Vроств, м3 | H19: Vгр, м3 | I19: Объем, м3
A20: № участка | B20: Захватки | C20: Длина лотка L, м | E20: V=0.200*1.700*2.000*N | F20: V=0.100*1.300*1.600*N | G20: V=0.900*1.200*0.500*N | H20: Vгр=(2.100+3.400)/2*0.800*L | I20: V=Vгр -Vщеб-Vподб-Vроств
A21: 3 | B21: Захватка 1 | C21: =Грунт!E16 -> 42.9 | D21: =Грунт!Q16 -> 3 | E21: =Щебень!G20 -> 1.62 | F21: =Подб_Роств!G20 -> 0.624 | G21: =Ростверки!G20 -> 1.944 | H21: =(2.1+3.4)/2*0.8*C21 -> 94.38 | I21: =H21-G21-F21-E21 -> 90.192
B22: Захватка 2 | C22: =Грунт!E17 -> 20.9 | D22: =Грунт!Q17 -> 6 | E22: =Щебень!G21 -> 3.24 | F22: =Подб_Роств!G21 -> 1.248 | G22: =Ростверки!G21 -> 3.888 | H22: =(2.1+3.4)/2*0.8*C22 -> 45.98 | I22: =H22-G22-F22-E22 -> 37.604
B23: Захватка 3 | C23: =Грунт!E18 -> 12.5 | D23: =Грунт!Q18 -> 0 | E23: =Щебень!G22 -> 0 | F23: =Подб_Роств!G22 -> 0 | G23: =Ростверки!G22 -> 0 | H23: =(2.1+3.4)/2*0.8*C23 -> 27.5 | I23: =H23-G23-F23-E23 -> 27.5
B24: Захватка 4 | C24: =Грунт!E19 -> 42.1 | D24: =Грунт!Q19 -> 3 | E24: =Щебень!G23 -> 1.62 | F24: =Подб_Роств!G23 -> 1.272 | G24: =Ростверки!G23 -> 2.7 | H24: =(2.1+3.4)/2*0.8*C24 -> 92.62 | I24: =H24-G24-F24-E24 -> 87.028
B25: TOTAL: | C25: =SUM(C21:C24) -> 118.4 | D25: =SUM(D21:D24) -> 12 | E25: =SUM(E21:E24) -> 6.48 | F25: =SUM(F21:F24) -> 3.144 | G25: =SUM(G21:G24) -> 8.532 | H25: =SUM(H21:H24) -> 260.48 | I25: =SUM(I21:I24) -> 242.324
A27: Расчет обратной засыпки ростверков при устройстве лотков
D28: Ростверки | E28: Щебень | F28: Подб_Роств | G28: Бетон Роств | H28: Обратная засыпка
D29: шт | E29: Vщеб, м3 | F29: Vподб м3 | G29: Vроств, м3 | H29: Vгр, м3 | I29: Объем, м3
A30: № участка | B30: Захватки | C30: Длина лотка L, м | E30: V=0.200*1.700*2.000*N | F30: V=0.100*1.300*1.600*N | G30: V=0.900*1.200*0.500*N | H30: Vгр=(2.100+3.400)/2*0.800*L | I30: V=Vгр -Vщеб-Vподб-Vроств
A31: 4 | B31: Захватка 1 | C31: =Грунт!E24 -> 80 | D31: =Грунт!Q24 -> 13 | E31: =Щебень!G32 -> 7.02 | F31: =Подб_Роств!G32 -> 2.704 | G31: =Ростверки!G32 -> 8.424 | H31: =(2.1+3.4)/2*0.8*C31 -> 176 | I31: =H31-G31-F31-E31 -> 157.852
B32: Захватка 2 | C32: =Грунт!E25 -> 23.3 | D32: =Грунт!Q25 -> 3 | E32: =Щебень!G33 -> 1.62 | F32: =Подб_Роств!G33 -> 0.624 | G32: =Ростверки!G33 -> 1.944 | H32: =(2.1+3.4)/2*0.8*C32 -> 51.26 | I32: =H32-G32-F32-E32 -> 47.072
B33: Захватка 3 | C33: =Грунт!E26 -> 58.5 | D33: =Грунт!Q26 -> 13 | E33: =Щебень!G34 -> 7.02 | F33: =Подб_Роств!G34 -> 2.704 | G33: =Ростверки!G34 -> 8.424 | H33: =(2.1+3.4)/2*0.8*C33 -> 128.7 | I33: =H33-G33-F33-E33 -> 110.552
B34: TOTAL: | C34: =SUM(C31:C33) -> 161.8 | D34: =SUM(D31:D33) -> 29 | E34: =SUM(E31:E33) -> 15.66 | F34: =SUM(F31:F33) -> 6.032 | G34: =SUM(G31:G33) -> 18.792 | H34: =SUM(H31:H33) -> 355.96 | I34: =SUM(I31:I33) -> 315.476
C36: =C34+C25+C15+C7 -> 408.1 | D36: =D34+D25+D15+D7 -> 60 | E36: =E34+E25+E15+E7 -> 32.4 | F36: =F34+F25+F15+F7 -> 13.128 | G36: =G34+G25+G15+G7 -> 39.636 | H36: =H34+H25+H15+H7 -> 897.82 | I36: =I34+I25+I15+I7 -> 812.656

Sheet Подб_Лотков
A1: Бетонное основание лотков, B15, B25 толщ. 100 мм/Concrete bed, B15, B25 th. 100 mm
E2: L | F2: N | G2: Вычисления, Calculation Объем , м3 | H2: Всего
A3: № участка | B3: Наименование работ | C3: Ед. изм. | D3: Захватки | E3: м | F3: Ростверки шт | G3: V=(1.5*L-0.9*1.2*N)*0.1
A4: 1 | B4: Бетонное основание | C4: м3 | D4: Захватка 1 | E4: =Грунт!E4 -> 17.5 | F4: =Грунт!Q4 -> 5 | G4: =(1.5*E4-0.9*1.2*F4)*0.1 -> 2.085 | H4: =SUM(G4:G5) -> 6.858
C5: м3 | D5: Захватка 2 | E5: =Грунт!E5 -> 34.7 | F5: =Грунт!Q5 -> 4 | G5: =(1.5*E5-0.9*1.2*F5)*0.1 -> 4.773
A7: Бетонное основание лотков, B15, B25 толщ. 100 мм/Concrete bed, B15, B25 th. 100 mm
E8: L | F8: N | G8: Вычисления, Calculation Объем , м3 | H8: Всего
A9: № участка | B9: Наименование работ | C9: Ед. изм. | D9: Захватки | E9: м | F9: Ростверки шт | G9: V=(1.5*L-0.9*1.2*N)*0.1
A10: 2 | B10: Бетонное основание | C10: м3 | D10: Захватка 1 | E10: =Грунт!E10 -> 54.2 | F10: =Грунт!Q10 -> 4 | G10: =(1.5*E10-0.9*1.2*F10)*0.1 -> 7.698 | H10: =SUM(G10:G11) -> 10.275
C11: м3 | D11: Захватка 2 | E11: =Грунт!E11 -> 21.5 | F11: =Грунт!Q11 -> 6 | G11: =(1.5*E11-0.9*1.2*F11)*0.1 -> 2.577
A13: Бетонное основание лотков, B15, B25 толщ. 100 мм/Concrete bed, B15, B25 th. 100 mm
E14: L | F14: N | G14: Вычисления, Calculation Объем , м3 | H14: Всего
A15: № участка | B15: Наименование работ | C15: Ед. изм. | D15: Захватки | E15: м | F15: Ростверки шт | G15: V=(1.5*L-0.9*1.2*N)*0.1
A16: 3 | B16: Бетонное основание | C16: м3 | D16: Захватка 1 | E16: =Грунт!E16 -> 42.9 | F16: =Грунт!Q16 -> 3 | G16: =(1.5*E16-0.9*1.2*F16)*0.1 -> 6.111 | H16: =SUM(G16:G19) -> 16.464
C17: м3 | D17: Захватка 2 | E17: =Грунт!E17 -> 20.9 | F17: =Грунт!Q17 -> 6 | G17: =(1.5*E17-0.9*1.2*F17)*0.1 -> 2.487
C18: м3 | D18: Захватка 3 | E18: =Грунт!E18 -> 12.5 | F18: =Грунт!Q18 -> 0 | G18: =(1.5*E18-0.9*1.2*F18)*0.1 -> 1.875
C19: м3 | D19: Захватка 4 | E19: =Грунт!E19 -> 42.1 | F19: =Грунт!Q19 -> 3 | G19: =(1.5*E19-0.9*1.2*F19)*0.1 -> 5.991
A21: Бетонное основание лотков, B15, толщ. 100 мм/Concrete bed, B15, th. 100 mm
E22: L | F22: N | G22: Вычисления, Calculation Объем , м3 | H22: Всего
A23: № участка | B23: Наименование работ | C23: Ед. изм. | D23: Захватки | E23: м | F23: Ростверки шт | G23: V=(1.5*L-0.9*1.2*N)*0.1
A24: 4 | B24: Бетонное основание | C24: м3 | D24: Захватка 1 | E24: =Грунт!E24 -> 80 | F24: =Грунт!Q24 -> 13 | G24: =(1.5*E24-0.9*1.2*F24)*0.1 -> 10.596 | H24: =SUM(G24:G26) -> 21.138
C25: м3 | D25: Захватка 2 | E25: =Грунт!E25 -> 23.3 | F25: =Грунт!Q25 -> 3 | G25: =(1.5*E25-0.9*1.2*F25)*0.1 -> 3.171
C26: м3 | D26: Захватка 3 | E26: =Грунт!E26 -> 58.5 | F26: =Грунт!Q26 -> 13 | G26: =(1.5*E26-0.9*1.2*F26)*0.1 -> 7.371
E28: =SUM(E4:E26) -> 408.1 | F28: =SUM(F4:F26) -> 60 | H28: =SUM(H4:H26) -> 54.735

Sheet Днище_Лотков
A1: Бетонирование днища лотков, B 30, W12, толщ. 300 мм/Concrete bed, B 30, W12, th. 300 mm
E2: L | F2: Вычисления, Calculation Объем , м3 | G2: Всего
A3: № участка | B3: Наименование работ | C3: Ед. изм. | D3: Захватки | E3: м | F3: V=0.9*0.3*L
A4: 1 | B4: Бетонирование днища лотков | C4: м3 | D4: Захватка 1 | E4: =Грунт!E4 -> 17.5 | F4: =0.9*0.3*E4 -> 4.725 | G4: =SUM(F4:F5) -> 14.094
C5: м3 | D5: Захватка 2 | E5: 34.7 | F5: =0.9*0.3*E5 -> 9.369
A7: Бетонирование днища лотков, B 30, W12, толщ. 300 мм/Concrete bed, B 30, W12, th. 300 mm
E8: L | F8: Вычисления, Calculation Объем , м3 | G8: Всего
A9: № участка | B9: Наименование работ | C9: Ед. изм. | D9: Захватки | E9: м | F9: V=0.9*0.3*L
A10: 2 | B10: Бетонирование днища лотков | C10: м3 | D10: Захватка 1 | E10: =Грунт!E10 -> 54.2 | F10: =0.9*0.3*E10 -> 14.634 | G10: =SUM(F10:F11) -> 20.439
C11: м3 | D11: Захватка 2 | E11: =Грунт!E11 -> 21.5 | F11: =0.9*0.3*E11 -> 5.805
A13: Бетонирование днища лотков, B 30, W12, толщ. 300 мм/Concrete bed, B 30, W12, th. 300 mm
E14: L | F14: Вычисления, Calculation Объем , м3 | G14: Всего
A15: № участка | B15: Наименование работ | C15: Ед. изм. | D15: Захватки | E15: м | F15: V=0.9*0.3*L
A16: 3 | B16: Бетонирование днища лотков | C16: м3 | D16: Захватка 1 | E16: =Грунт!E16 -> 42.9 | F16: =0.9*0.3*E16 -> 11.583 | G16: =SUM(F16:F19) -> 37.701
C17: м3 | D17: Захватка 2 | E17: =Грунт!E17 -> 20.9 | F17: =0.9*0.3*E17 -> 5.643
C18: м3 | D18: Захватка 3 | E18: =Грунт!E18 -> 12.5 | F18: =1.25*0.3*E18 -> 4.6875
C19: м3 | D19: Захватка 4 | E19: =Грунт!E19 -> 42.1 | F19: =1.25*0.3*E19 -> 15.7875
A21: Бетонирование днища лотков, B 30, W12, толщ. 300 мм/Concrete bed, B 30, W12, th. 300 mm
E22: L | F22: Вычисления, Calculation Объем , м3 | G22: Всего
A23: № участка | B23: Наименование работ | C23: Ед. изм. | D23: Захватки | E23: м | F23: V=0.9*0.3*L
A24: 4 | B24: Бетонирование днища лотков | C24: м3 | D24: Захватка 1 | E24: =Грунт!E24 -> 80 | F24: =0.9*0.3*E24 -> 21.6 | G24: =SUM(F24:F26) -> 43.686
C25: м3 | D25: Захватка 2 | E25: =Грунт!E25 -> 23.3 | F25: =0.9*0.3*E25 -> 6.291
C26: м3 | D26: Захватка 3 | E26: =Грунт!E26 -> 58.5 | F26: =0.9*0.3*E26 -> 15.795
E28: =SUM(E4:E26) -> 408.1 | G28: =SUM(G4:G26) -> 115.92

Sheet Шпонка_Днища
A1: Гидрошпонка днища лотков
E2: L | F2: Вычисления, Calculation Длина , м | G2: Всего
A3: № участка | B3: Наименование работ | C3: Ед. изм. | D3: Захватки | E3: м | F3: Lшп=L*2+0,9*2
A4: 1 | B4: Гидрошпонка днища лотков | C4: м3 | D4: Захватка 1 | E4: =Грунт!E4 -> 17.5 | F4: =E4*2+0.9*2 -> 36.8 | G4: =SUM(F4:F5) -> 108
C5: м3 | D5: Захватка 2 | E5: 34.7 | F5: =E5*2+0.9*2 -> 71.2
A7: Гидрошпонка днища лотков
E8: L | F8: Вычисления, Calculation Длина , м | G8: Всего
A9: № участка | B9: Наименование работ | C9: Ед. изм. | D9: Захватки | E9: м | F9: Lшп=L*2+0,9*2
A10: 2 | B10: Гидрошпонка днища лотков | C10: м3 | D10: Захватка 1 | E10: =Грунт!E10 -> 54.2 | F10: =E10*2+0.9*2 -> 110.2 | G10: =SUM(F10:F11) -> 155
C11: м3 | D11: Захватка 2 | E11: =Грунт!E11 -> 21.5 | F11: =E11*2+0.9*2 -> 44.8
A13: Гидрошпонка днища лотков
E14: L | F14: Вычисления, Calculation Длина , м | G14: Всего
A15: № участка | B15: Наименование работ | C15: Ед. изм. | D15: Захватки | E15: м | F15: Lшп=L*2+0,9*2
A16: 3 | B16: Гидрошпонка днища лотков | C16: м3 | D16: Захватка 1 | E16: =Грунт!E16 -> 42.9 | F16: =E16*2+0.9*2 -> 87.6 | G16: =SUM(F16:F19) -> 244
C17: м3 | D17: Захватка 2 | E17: =Грунт!E17 -> 20.9 | F17: =E17*2+0.9*2 -> 43.6
C18: м3 | D18: Захватка 3 | E18: =Грунт!E18 -> 12.5 | F18: =E18*2+0.9*2 -> 26.8
C19: м3 | D19: Захватка 4 | E19: =Грунт!E19 -> 42.1 | F19: =E19*2+0.9*2 -> 86
A21: Гидрошпонка днища лотков
E22: L | F22: Вычисления, Calculation Длина , м | G22: Всего
A23: № участка | B23: Наименование работ | C23: Ед. изм. | D23: Захватки | E23: м | F23: Lшп=L*2+0,9*2
A24: 4 | B24: Гидрошпонка днища лотков | C24: м3 | D24: Захватка 1 | E24: =Грунт!E24 -> 80 | F24: =E24*2+0.9*2 -> 161.8 | G24: =SUM(F24:F26) -> 329
C25: м3 | D25: Захватка 2 | E25: =Грунт!E25 -> 23.3 | F25: =E25*2+0.9*2 -> 48.4
C26: м3 | D26: Захватка 3 | E26: =Грунт!E26 -> 58.5 | F26: =E26*2+0.9*2 -> 118.8
E28: =SUM(E4:E26) -> 408.1 | G28: =SUM(G4:G26) -> 836

Sheet Стены_Лотков
A1: Расчет бетонирования стен лотков | O1: Гидроизоляция подб | P1: Гидроизоляция стен
G2: Средняя высота hср, м | J2: Вычисления, Calculation Сечение, м2 | M2: Объем, м3 | O2: S, м2 | P2: S, м2 | R2: Площадь стен
A3: № участка | B3: Захватки | C3: Длина лотка L, м | E3: Нач. | F3: Кон. | G3: hср=(hmin+hmax)/2-0.250 | J3: S=0.200*2*hср | M3: V=Sср*L | O3: S=2_слоя*L*1.5 | P3: S=2_слоя*L(2*h_днища+2*h_стен+2*h_усилен)
A4: 1 | B4: Захватка 1 | C4: =Грунт!E4 -> 17.5 | D4: hср= | E4: 0.45 | F4: 0.68 | G4: hср= | H4: =CONCATENATE("(",E4,"+",F4,")/2-0.250") -> (0,45+0,68)/2-0.250 | I4: =(E4+F4)/2-0.25 -> 0.315 | J4: Sср= | K4: 0.200*2*hср = | L4: =0.2*2*I4 -> 0.126 | M4: =L4*C4 -> 2.205 | O4: =2*C4*1.5 -> 52.5 | P4: =2*C4*(2*0.3+2*I4+2*0.6) -> 85.05 | R4: =C4*I4*2 -> 11.025
B5: Захватка 2 | C5: 34.7 | D5: hср= | E5: 1.99 | F5: 2.06 | G5: hср= | H5: =CONCATENATE("(",E5,"+",F5,")/2-0.500") -> (1,99+2,06)/2-0.500 | I5: =(E5+F5)/2-0.5 -> 1.525 | J5: Sср= | K5: 0.200*2*hср = | L5: =0.2*2*I5 -> 0.61 | M5: =L5*C5 -> 21.167 | O5: =2*C5*1.5 -> 104.1 | P5: =2*C5*(2*0.3+2*I5+2*0.6) -> 336.59 | R5: =C5*I5*2 -> 105.835
M6: =SUM(M4:M5) -> 23.372 | O6: =SUM(O4:O5) -> 156.6 | P6: =SUM(P4:P5) -> 421.64 | R6: =SUM(R4:R5) -> 116.86
A8: Расчет бетонирования стен лотков | O8: Гидроизоляция подб | P8: Гидроизоляция стен
G9: Средняя высота hср, м | J9: Вычисления, Calculation Сечение, м2 | M9: Объем, м3 | O9: S, м2 | P9: S, м2
A10: № участка | B10: Захватки | C10: Длина лотка L, м | E10: Нач. | F10: Кон. | G10: hср=(hmin+hmax)/2-hсущ. | M10: V=Sср*L | O10: S=2_слоя*L*1.5 | P10: S=2_слоя*L(2*h_днища+2*h_стен+2*h_усилен)
A11: 2 | B11: Захватка 1 | C11: =Грунт!E10 -> 54.2 | D11: hср= | E11: 1.985 | F11: 2.69 | G11: hср= | H11: =CONCATENATE("(",E11,"+",F11,")/2-0.250") -> (1,985+2,69)/2-0.250 | I11: =(E11+F11)/2-0.25 -> 2.0875 | J11: Sср= | K11: 0.200*2*hср = | L11: =0.2*2*I11 -> 0.835 | M11: =L11*C11 -> 45.257 | O11: =2*C11*1.5 -> 162.6 | P11: =2*C11*(2*0.3+2*I11+2*0.6) -> 647.69 | R11: =C11*I11*2 -> 226.285 | S11: =2869-900 -> 1969
B12: Захватка 2 | C12: =Грунт!E11 -> 21.5 | D12: hср= | E12: 0.45 | F12: 0.74 | G12: hср= | H12: =CONCATENATE("(",E12,"+",F12,")/2-0.250") -> (0,45+0,74)/2-0.250 | I12: =(E12+F12)/2-0.25 -> 0.345 | J12: Sср= | K12: 0.200*2*hср = | L12: =0.2*2*I12 -> 0.138 | M12: =L12*C12 -> 2.967 | O12: =2*C12*1.5 -> 64.5 | P12: =2*C12*(2*0.3+2*I12+2*0.6) -> 107.07 | R12: =C12*I12*2 -> 14.835
M13: =SUM(M11:M12) -> 48.224 | O13: =SUM(O11:O12) -> 227.1 | P13: =SUM(P11:P12) -> 754.76 | R13: =SUM(R11:R12) -> 241.12
A15: Расчет бетонирования стен лотков | O15: Гидроизоляция подб | P15: Гидроизоляция стен
G16: Средняя высота hср, м | J16: Вычисления, Calculation Сечение, м2 | M16: Объем, м3 | O16: S, м2 | P16: S, м2
A17: № участка | B17: Захватки | C17: Длина лотка L, м | E17: Нач. | F17: Кон. | G17: hср=(hmin+hmax)/2-0.250 | M17: V=Sср*L | O17: S=2_слоя*L*1.5 | P17: S=2_слоя*L(2*h_днища+2*h_стен+2*h_усилен)
A18: 3 | B18: Захватка 1 | C18: =Грунт!E16 -> 42.9 | D18: hср= | E18: 1.98 | F18: 2.69 | G18: hср= | H18: =CONCATENATE("(",E18,"+",F18,")/2-0.250") -> (1,98+2,69)/2-0.250 | I18: =(E18+F18)/2-0.25 -> 2.085 | J18: Sср= | K18: 0.200*2*hср = | L18: =0.2*2*I18 -> 0.834 | M18: =L18*C18 -> 35.7786 | O18: =2*C18*1.5 -> 128.7 | P18: =2*C18*(2*0.3+2*I18+2*0.6) -> 512.226 | R18: =C18*I18*2 -> 178.893
B19: Захватка 2 | C19: =Грунт!E17 -> 20.9 | D19: hср= | E19: 0.9 | F19: 1.33 | G19: hср= | H19: =CONCATENATE("(",E19,"+",F19,")/2-0.250") -> (0,9+1,33)/2-0.250 | I19: =(E19+F19)/2-0.25 -> 0.865 | J19: Sср= | K19: 0.200*2*hср = | L19: =0.2*2*I19 -> 0.346 | M19: =L19*C19 -> 7.2314 | O19: =2*C19*1.5 -> 62.7 | P19: =2*C19*(2*0.3+2*I19+2*0.6) -> 147.554 | R19: =C19*I19*2 -> 36.157
B20: Захватка 3 | C20: =Грунт!E18 -> 12.5 | D20: hср= | E20: 1.4 | F20: 1.6 | G20: hср= | H20: =CONCATENATE("(",E20,"+",F20,")/2-0.250") -> (1,4+1,6)/2-0.250 | I20: =(E20+F20)/2-0.25 -> 1.25 | J20: Sср= | K20: 0.200*2*hср = | L20: =0.2*2*I20 -> 0.5 | M20: =L20*C20 -> 6.25 | O20: =2*C20*1.5 -> 37.5 | P20: =2*C20*(2*0.3+2*I20+2*0.6) -> 107.5 | R20: =C20*I20*2 -> 31.25
B21: Захватка 4 | C21: =Грунт!E19 -> 42.1 | D21: hср= | E21: 1.76 | F21: 2.3 | G21: hср= | H21: =CONCATENATE("(",E21,"+",F21,")/2-0.250") -> (1,76+2,3)/2-0.250 | I21: =(E21+F21)/2-0.25 -> 1.78 | J21: Sср= | K21: 0.400*2*hср = | L21: =0.4*2*I21 -> 1.424 | M21: =L21*C21 -> 59.9504 | O21: =2*C21*1.5 -> 126.3 | P21: =2*C21*(2*0.3+2*I21+2*0.6) -> 451.312 | R21: =C21*I21*2 -> 149.876
M22: =SUM(M18:M21) -> 109.2104 | O22: =SUM(O18:O21) -> 355.2 | P22: =SUM(P18:P21) -> 1218.592 | R22: =SUM(R18:R21) -> 396.176
A24: Расчет бетонирования стен лотков | O24: Гидроизоляция подб | P24: Гидроизоляция стен
G25: высота стенок | J25: Вычисления, Calculation Сечение, м2 | M25: Объем, м3 | O25: S, м2 | P25: S, м2
A26: № участка | B26: Захватки | C26: Длина лотка L, м | E26: Нач. | F26: Кон. | G26: hср=(hmin+hmax)/2-0.250 | J26: S=0.200*2*hср | M26: V=Sср*L | O26: S=2_слоя*L*1.5 | P26: S=2_слоя*L(2*h_днища+2*h_стен+2*h_усилен)
A27: 4 | B27: Захватка 1 | C27: =Грунт!E24 -> 80 | D27: hср= | E27: 1.4 | F27: 2.2 | G27: hср= | H27: =CONCATENATE("(",E27,"+",F27,")/2-0.250") -> (1,4+2,2)/2-0.250 | I27: =(E27+F27)/2-0.25 -> 1.55 | J27: Sср= | K27: 0.200*2*hср = | L27: =0.2*2*I27 -> 0.62 | M27: =L27*C27 -> 49.6 | O27: =2*C27*1.5 -> 240 | P27: =2*C27*(2*0.3+2*I27+2*0.6) -> 784 | R27: =C27*I27*2 -> 248
B28: Захватка 2 | C28: =Грунт!E25 -> 23.3 | D28: hср= | E28: 1.42 | F28: 1.721 | G28: hср= | H28: =CONCATENATE("(",E28,"+",F28,")/2-0.250") -> (1,42+1,721)/2-0.250 | I28: =(E28+F28)/2-0.25 -> 1.3205 | J28: Sср= | K28: 0.200*2*hср = | L28: =0.2*2*I28 -> 0.5282 | M28: =L28*C28 -> 12.30706 | O28: =2*C28*1.5 -> 69.9 | P28: =2*C28*(2*0.3+2*I28+2*0.6) -> 206.9506 | R28: =C28*I28*2 -> 61.5353
B29: Захватка 3 | C29: =Грунт!E26 -> 58.5 | E29: 0.45 | F29: 0.725 | G29: hср= | H29: =CONCATENATE("(",E29,"+",F29,")/2-0.250") -> (0,45+0,725)/2-0.250 | I29: =(E29+F29)/2-0.25 -> 0.3375 | J29: Sср= | K29: 0.200*2*hср = | L29: =0.2*2*I29 -> 0.135 | M29: =L29*C29 -> 7.8975 | O29: =2*C29*1.5 -> 175.5 | P29: =2*C29*(2*0.3+2*I29+2*0.6) -> 289.575 | R29: =C29*I29*2 -> 39.4875
M30: =SUM(M27:M29) -> 69.80456 | O30: =SUM(O27:O29) -> 485.4 | P30: =SUM(P27:P29) -> 1280.5256 | R30: =SUM(R26:R29) -> 349.0228
M32: =M6+M13+M22+M30 -> 250.61096 | O32: =O6+O13+O22+O30 -> 1224.3 | P32: =P6+P13+P22+P30 -> 3675.5176 | R32: =R6+R13+R22+R30 -> 1103.1788
O34: =O32+P32 -> 4899.8176
D37: Бетон 13.11.2020
A39: стенки с двутавром | C39: 2.45 | D39: hср= | E39: 0.985 | F39: 0.985 | G39: hср= | H39: =CONCATENATE("(",E39,"+",F39,")/2-0.212") -> (0,985+0,985)/2-0.212 | I39: =(E39+F39)/2-0.212 -> 0.773 | J39: Sср= | K39: 0.400*2*hср = | L39: =0.4*2*I39 -> 0.6184 | M39: =L39*C39 -> 1.51508
C41: =4.47-2.45 -> 2.02 | D41: hср= | E41: 0.985 | F41: 0.985 | G41: hср= | H41: =CONCATENATE("(",E41,"+",F41,")/2-0.250") -> (0,985+0,985)/2-0.250 | I41: =(E41+F41)/2-0.25 -> 0.735 | J41: Sср= | K41: 0.200*2*hср = | L41: =0.2*2*I41 -> 0.294 | M41: =L41*C41 -> 0.59388
A43: 3 подб роств\ | M43: =1.6*1.3*3*0.1 -> 0.624
A46: 5 балконов подбет | M46: =1.5*0.95*5*0.1 -> 0.7125
K48: ИТОГО: | M48: =SUM(M39:M46) -> 3.44546
A51: днище | C51: =4*0.65 -> 2.6 | M51: =C51*0.3*0.9 -> 0.702
A53: стенки | C53: =4*(0.65*2+0.5) -> 7.2 | D53: hср= | E53: 0.5 | F53: 0.45 | G53: hср= | H53: =CONCATENATE("(",E53,"+",F53,")/2-0.250") -> (0,5+0,45)/2-0.250 | I53: =(E53+F53)/2-0.25 -> 0.225 | J53: Sср= | K53: 0.200*2*hср = | L53: =0.2*2*I53 -> 0.09 | M53: =L53*C53 -> 0.648
M55: =SUM(M51:M53) -> 1.35
H57: 44163
A59: Подбетонка | C59: 11.6х1.7*0.300 | M59: =11.6*1.7*0.3 -> 5.916
...

Sheet Шпонка_Стен
A1: Гидрошпонка стен лотков
E2: L | F2: Вычисления, Calculation Длина , м | G2: Всего
A3: № участка | B3: Наименование работ | C3: Ед. изм. | D3: Захватки | E3: м | F3: Lшп=L*2+0,9*2
A4: 1 | B4: Гидрошпонка стен лотков | C4: м3 | D4: Захватка 1 | E4: =Грунт!E4 -> 17.5 | F4: =E4*2+0.9*2 -> 36.8 | G4: =SUM(F4:F5) -> 108
C5: м3 | D5: Захватка 2 | E5: 34.7 | F5: =E5*2+0.9*2 -> 71.2
A7: Гидрошпонка стен лотков
E8: L | F8: Вычисления, Calculation Длина , м | G8: Всего
A9: № участка | B9: Наименование работ | C9: Ед. изм. | D9: Захватки | E9: м | F9: Lшп=L*2+0,9*2
A10: 2 | B10: Гидрошпонка стен лотков | C10: м3 | D10: Захватка 1 | E10: =Грунт!E10 -> 54.2 | F10: =E10*2+0.9*2 -> 110.2 | G10: =SUM(F10:F11) -> 155
C11: м3 | D11: Захватка 2 | E11: =Грунт!E11 -> 21.5 | F11: =E11*2+0.9*2 -> 44.8
A13: Гидрошпонка стен лотков
E14: L | F14: Вычисления, Calculation Длина , м | G14: Всего
A15: № участка | B15: Наименование работ | C15: Ед. изм. | D15: Захватки | E15: м | F15: Lшп=L*2+0,9*2
A16: 3 | B16: Гидрошпонка стен лотков | C16: м3 | D16: Захватка 1 | E16: =Грунт!E16 -> 42.9 | F16: =E16*2+0.9*2 -> 87.6 | G16: =SUM(F16:F19) -> 244
C17: м3 | D17: Захватка 2 | E17: =Грунт!E17 -> 20.9 | F17: =E17*2+0.9*2 -> 43.6
C18: м3 | D18: Захватка 3 | E18: =Грунт!E18 -> 12.5 | F18: =E18*2+0.9*2 -> 26.8
C19: м3 | D19: Захватка 4 | E19: =Грунт!E19 -> 42.1 | F19: =E19*2+0.9*2 -> 86
A21: Гидрошпонка стен лотков
E22: L | F22: Вычисления, Calculation Длина , м | G22: Всего
A23: № участка | B23: Наименование работ | C23: Ед. изм. | D23: Захватки | E23: м | F23: Lшп=L*2+0,9*2
A24: 4 | B24: Гидрошпонка стен лотков | C24: м3 | D24: Захватка 1 | E24: =Грунт!E24 -> 80 | F24: =E24*2+0.9*2 -> 161.8 | G24: =SUM(F24:F26) -> 329
C25: м3 | D25: Захватка 2 | E25: =Грунт!E25 -> 23.3 | F25: =E25*2+0.9*2 -> 48.4
C26: м3 | D26: Захватка 3 | E26: =Грунт!E26 -> 58.5 | F26: =E26*2+0.9*2 -> 118.8
E28: =SUM(E4:E26) -> 408.1 | G28: =SUM(G4:G26) -> 836 | I28: Тип - 1
